<?xml version="1.0"?>
<robot xmlns:xacro="http://www.ros.org/wiki/xacro">

  <xacro:parameter name="pi" value="3.1415"/>


    <transmission name="xtion_pan_trans">
      <type>transmission_interface/SimpleTransmission</type>
      <joint name="xtion_pan">
        <hardwareInterface>PositionJointInterface</hardwareInterface>
      </joint>
      <actuator name="xtion_pan_motor">
        <hardwareInterface>PositionJointInterface</hardwareInterface>
        <mechanicalReduction>1</mechanicalReduction>
      </actuator>
    </transmission>

    <transmission name="xtion_tilt_trans">
      <type>transmission_interface/SimpleTransmission</type>
      <joint name="xtion_tilt">
        <hardwareInterface>PositionJointInterface</hardwareInterface>
      </joint>
      <actuator name="xtion_tilt_motor">
        <hardwareInterface>PositionJointInterface</hardwareInterface>
        <mechanicalReduction>1</mechanicalReduction>
      </actuator>
    </transmission>


    <link name="xtion_base">
      <inertial>
        <origin xyz="0 0 0" rpy="0 0 0"/>
        <mass value="0.01"/>
        <inertia ixx="0.01"  ixy="0"  ixz="0" iyy="0.01" iyz="0" izz="0.01" />
      </inertial>  
      <visual>
            <origin xyz="0 0 0" rpy="0 0 0"/>
            <geometry>
                <box size="0.10 0.10 0.02" />
            </geometry>
        </visual> 
    </link>


    <joint name="xtion_pan" type="revolute">
        <parent link="xtion_base"/>
        <child link="xtion_inter_link"/>
        <origin xyz="0 0 0.075" rpy="0 0 0"/>
        <axis xyz="0 0 1"/>
        <limit effort="1.0" velocity="1.0" lower="-3.1415" upper="3.1415"/>
    </joint>
    

    <link name="xtion_inter_link">
      <inertial>
        <origin xyz="0 0 0" rpy="0 0 0"/>
        <mass value="0.01"/>
        <inertia ixx="0.01"  ixy="0"  ixz="0" iyy="0.01" iyz="0" izz="0.01" />
      </inertial>  
      <visual>
            <origin xyz="0 0 0" rpy="0 0 0"/>
            <geometry>
                <box size="0.03 0.03 0.03" />
            </geometry>
        </visual> 
    </link>

    <joint name="xtion_tilt" type="revolute">
        <origin xyz="0 0 0.045" rpy="0 0 0"/>
        <parent link="xtion_inter_link"/>
        <child link="xtion_proto_link"/>
        <axis xyz=" 1 0 0"/>
        <limit effort="1.0" velocity="1.0" lower="-3.1415" upper="3.1415"/>
    </joint>
    

    <link name="xtion_proto_link">
      <inertial>
        <origin xyz="0 0 0" rpy="0 0 0"/>
        <mass value="0.01"/>
        <inertia ixx="0.01"  ixy="0"  ixz="0" iyy="0.01" iyz="0" izz="0.01" />
      </inertial>
    </link>


    <joint name="xtion_attachment" type="fixed">
        <parent link="xtion_proto_link"/>
        <child link="xtion_camera_link"/>
        <origin xyz="0 0 0.07" rpy="0 0 3.1415"/>
        <axis xyz="0 0 1"/>
    </joint>

    <link name="xtion_camera_link">
      <inertial>
        <origin xyz="0 0 0" rpy="0 0 0"/>
        <mass value="0.01"/>
        <inertia ixx="0.01"  ixy="0"  ixz="0" iyy="0.01" iyz="0" izz="0.01" />
      </inertial>
      <visual>
            <origin xyz="0 0 0" rpy="0 0 0"/>
            <geometry>
                <box size="0.15 0.02 0.02" />
            </geometry>
        </visual> 
    </link>

    <joint name="xtion_etc1" type="fixed">
        <parent link="xtion_camera_link"/>
        <child link="camera_depth_optical_frame"/>
        <origin xyz="0 0 0.0" rpy="1.5707 3.1415 0"/>
        <axis xyz="0 0 1"/>
    </joint>

    <link name="camera_depth_optical_frame">
      <inertial>
        <origin xyz="0 0 0" rpy="0 0 0"/>
        <mass value="0.01"/>
        <inertia ixx="0.01"  ixy="0"  ixz="0" iyy="0.01" iyz="0" izz="0.01" />
      </inertial>
    </link>

<!--
    <gazebo reference="xtion_camera_link">
        <sensor type="camera" name="xtion">
          <update_rate>30.0</update_rate>
          <camera name="xtion">
            <horizontal_fov>1.3962634</horizontal_fov>
            <image>
              <width>800</width>
              <height>800</height>
              <format>R8G8B8</format>
            </image>
            <clip>
              <near>0.02</near>
              <far>300</far>
            </clip>
            <noise>
              <type>gaussian</type>
              <!- Noise is sampled independently per pixel on each frame.
                   That pixel's noise value is added to each of its color
                   channels, which at that point lie in the range [0,1]. ->
                   
              <mean>0.0</mean>
              <stddev>0.007</stddev>
            </noise>
          </camera>
          <plugin name="camera_controller" filename="libgazebo_ros_camera.so">
            <alwaysOn>true</alwaysOn>
            <updateRate>0.0</updateRate>
            <cameraName>centaur/${name}</cameraName>
            <imageTopicName>image_raw</imageTopicName>
            <cameraInfoTopicName>camera_info</cameraInfoTopicName>
            <frameName>camera_link</frameName>
            <hackBaseline>0.07</hackBaseline>
            <distortionK1>0.0</distortionK1>
            <distortionK2>0.0</distortionK2>
            <distortionK3>0.0</distortionK3>
            <distortionT1>0.0</distortionT1>
            <distortionT2>0.0</distortionT2>
          </plugin>
        </sensor>
    </gazebo>
  -->

</robot>